[32m2022-07-06 10:59:47 +0000[0m - dagster - [34mDEBUG[0m - run_airbyte - d8b342e7-69c4-4240-98b8-670d46bf448b - 18782 - sync_salesforce - LOGS_CAPTURED - Started capturing logs for step: sync_salesforce.
[32m2022-07-06 10:59:47 +0000[0m - dagster - [34mDEBUG[0m - run_airbyte - d8b342e7-69c4-4240-98b8-670d46bf448b - 18782 - sync_salesforce - STEP_START - Started execution of step "sync_salesforce".
[32m2022-07-06 10:59:47 +0000[0m - dagster - [34mERROR[0m - [31mresource:airbyte - d8b342e7-69c4-4240-98b8-670d46bf448b - sync_salesforce - Request to Airbyte API failed: HTTPConnectionPool(host='localhost', port=8000): Max retries exceeded with url: /api/v1/connections/get (Caused by NewConnectionError('<urllib3.connection.HTTPConnection object at 0x7feb38f6eb90>: Failed to establish a new connection: [Errno 111] Connection refused'))[0m
[32m2022-07-06 10:59:47 +0000[0m - dagster - [34mERROR[0m - [31mresource:airbyte - d8b342e7-69c4-4240-98b8-670d46bf448b - sync_salesforce - Request to Airbyte API failed: HTTPConnectionPool(host='localhost', port=8000): Max retries exceeded with url: /api/v1/connections/get (Caused by NewConnectionError('<urllib3.connection.HTTPConnection object at 0x7feb38f2e590>: Failed to establish a new connection: [Errno 111] Connection refused'))[0m
[32m2022-07-06 10:59:48 +0000[0m - dagster - [34mERROR[0m - [31mresource:airbyte - d8b342e7-69c4-4240-98b8-670d46bf448b - sync_salesforce - Request to Airbyte API failed: HTTPConnectionPool(host='localhost', port=8000): Max retries exceeded with url: /api/v1/connections/get (Caused by NewConnectionError('<urllib3.connection.HTTPConnection object at 0x7feb38f3e8d0>: Failed to establish a new connection: [Errno 111] Connection refused'))[0m
[32m2022-07-06 10:59:48 +0000[0m - dagster - [34mERROR[0m - [31mresource:airbyte - d8b342e7-69c4-4240-98b8-670d46bf448b - sync_salesforce - Request to Airbyte API failed: HTTPConnectionPool(host='localhost', port=8000): Max retries exceeded with url: /api/v1/connections/get (Caused by NewConnectionError('<urllib3.connection.HTTPConnection object at 0x7feb38f2efd0>: Failed to establish a new connection: [Errno 111] Connection refused'))[0m
[32m2022-07-06 10:59:48 +0000[0m - dagster - [34mERROR[0m - [31mrun_airbyte - d8b342e7-69c4-4240-98b8-670d46bf448b - 18782 - sync_salesforce - STEP_FAILURE - Execution of step "sync_salesforce" failed.

dagster.core.definitions.events.Failure: Exceeded max number of retries.

Stack Trace:
  File "/home/ec2-user/dagster/dagster-test/orchestrator_poc/.venv/lib64/python3.7/site-packages/dagster/core/execution/plan/execute_plan.py", line 224, in dagster_event_sequence_for_step
    for step_event in check.generator(step_events):
  File "/home/ec2-user/dagster/dagster-test/orchestrator_poc/.venv/lib64/python3.7/site-packages/dagster/core/execution/plan/execute_step.py", line 354, in core_dagster_event_sequence_for_step
    _step_output_error_checked_user_event_sequence(step_context, user_event_sequence)
  File "/home/ec2-user/dagster/dagster-test/orchestrator_poc/.venv/lib64/python3.7/site-packages/dagster/core/execution/plan/execute_step.py", line 69, in _step_output_error_checked_user_event_sequence
    for user_event in user_event_sequence:
  File "/home/ec2-user/dagster/dagster-test/orchestrator_poc/.venv/lib64/python3.7/site-packages/dagster/core/execution/plan/compute.py", line 174, in execute_core_compute
    for step_output in _yield_compute_results(step_context, inputs, compute_fn):
  File "/home/ec2-user/dagster/dagster-test/orchestrator_poc/.venv/lib64/python3.7/site-packages/dagster/core/execution/plan/compute.py", line 151, in _yield_compute_results
    user_event_generator,
  File "/home/ec2-user/dagster/dagster-test/orchestrator_poc/.venv/lib64/python3.7/site-packages/dagster/utils/__init__.py", line 406, in iterate_with_context
    next_output = next(iterator)
  File "/home/ec2-user/dagster/dagster-test/orchestrator_poc/.venv/lib64/python3.7/site-packages/dagster_airbyte/ops.py", line 93, in airbyte_sync_op
    poll_timeout=context.op_config["poll_timeout"],
  File "/home/ec2-user/dagster/dagster-test/orchestrator_poc/.venv/lib64/python3.7/site-packages/dagster_airbyte/resources.py", line 132, in sync_and_poll
    connection_details = self.get_connection_details(connection_id)
  File "/home/ec2-user/dagster/dagster-test/orchestrator_poc/.venv/lib64/python3.7/site-packages/dagster_airbyte/resources.py", line 109, in get_connection_details
    self.make_request(endpoint="/connections/get", data={"connectionId": connection_id})
  File "/home/ec2-user/dagster/dagster-test/orchestrator_poc/.venv/lib64/python3.7/site-packages/dagster_airbyte/resources.py", line 94, in make_request
    raise Failure("Exceeded max number of retries.")
[0m
